Workbook
Name _xlcn.WorksheetConnection_FlightBookingandTravelDataAnalysis11.xlsxTable51: #REF!
Name _xlcn.WorksheetConnection_FlightBookingandTravelDataAnalysis.xlsxTable11: #REF!
Name _xlcn.WorksheetConnection_FlightBookingandTravelDataAnalysis11.xlsxTable21: #REF!
Name _xlcn.WorksheetConnection_FlightBookingandTravelDataAnalysis11.xlsxTable41: #REF!

Sheet Airlines
A1: Airline_Id | B1: Airline_Name | C1: Total_Bookings | D1: unique_flights | E1: Routes_Covered | F1: Avg_Price | G1: Min_Price | H1: Max_Price | I1: Economy_Bookings | J1: Business_Bookings
A2: AL100 | B2: AirAsia | C2: 61 | D2: 61 | E2: 27 | F2: 3930.5246 | G2: 1443 | H2: 7484 | I2: 61 | J2: 0
A3: AL101 | B3: Air_India | C3: 421 | D3: 421 | E3: 30 | F3: 18373.679 | G3: 1526 | H3: 75382 | I3: 314 | J3: 107
A4: AL102 | B4: Go_First | C4: 109 | D4: 109 | E4: 26 | F4: 6339.7156 | G4: 2124 | H4: 31773 | I4: 109 | J4: 0
A5: AL103 | B5: Indigo | C5: 225 | D5: 225 | E5: 30 | F5: 5847.9778 | G5: 1105 | H5: 24561 | I5: 225 | J5: 0
A6: AL104 | B6: Spicejet | C6: 46 | D6: 46 | E6: 22 | F6: 6134.9783 | G6: 1566 | H6: 27769 | I6: 46 | J6: 0
A7: AL105 | B7: Vistara | C7: 338 | D7: 338 | E7: 30 | F7: 25590.518 | G7: 1776 | H7: 110936 | I7: 222 | J7: 116

Sheet Bookings
A1: Booking_Id | B1: Flight_Id | C1: Route_Id | D1: Airline_Id | E1: Airline_Name | F1: Class | G1: Stops | H1: Duration | I1: Days_Left | J1: Booking_Window | K1: Price
A2: BK1000 | B2: FLT10002 | C2: RT1 | D2: AL100 | E2: AirAsia | F2: Economy | G2: 0 | H2: 2.17 | I2: 14 | J2: =IF(I2<=7,"Last Minute",IF(I2<=15,"Short Notice",IF(I2<=30,"Moderate",IF(I2>=31,"Advance")))) -> Short Notice | K2: 5956
A3: BK1001 | B3: FLT10006 | C3: RT1 | D3: AL105 | E3: Vistara | F3: Business | G3: 0 | H3: 2.08 | I3: 15 | J3: =IF(I3<=7,"Last Minute",IF(I3<=15,"Short Notice",IF(I3<=30,"Moderate",IF(I3>=31,"Advance")))) -> Short Notice | K3: 28872
A4: BK1002 | B4: FLT10010 | C4: RT1 | D4: AL102 | E4: Go_First | F4: Economy | G4: 0 | H4: 2.25 | I4: 30 | J4: =IF(I4<=7,"Last Minute",IF(I4<=15,"Short Notice",IF(I4<=30,"Moderate",IF(I4>=31,"Advance")))) -> Moderate | K4: 2410
A5: BK1003 | B5: FLT10030 | C5: RT1 | D5: AL102 | E5: Go_First | F5: Economy | G5: 1 | H5: 8 | I5: 38 | J5: =IF(I5<=7,"Last Minute",IF(I5<=15,"Short Notice",IF(I5<=30,"Moderate",IF(I5>=31,"Advance")))) -> Advance | K5: 7907
A6: BK1004 | B6: FLT10070 | C6: RT1 | D6: AL105 | E6: Vistara | F6: Business | G6: 1 | H6: 26.42 | I6: 19 | J6: =IF(I6<=7,"Last Minute",IF(I6<=15,"Short Notice",IF(I6<=30,"Moderate",IF(I6>=31,"Advance")))) -> Moderate | K6: 41281
A7: BK1005 | B7: FLT10073 | C7: RT1 | D7: AL105 | E7: Vistara | F7: Business | G7: 1 | H7: 13.83 | J7: =IF(I7<=7,"Last Minute",IF(I7<=15,"Short Notice",IF(I7<=30,"Moderate",IF(I7>=31,"Advance")))) -> Last Minute | K7: 70793
A8: BK1006 | B8: FLT10077 | C8: RT1 | D8: AL105 | E8: Vistara | F8: Economy | G8: 1 | H8: 24.42 | I8: 2 | J8: =IF(I8<=7,"Last Minute",IF(I8<=15,"Short Notice",IF(I8<=30,"Moderate",IF(I8>=31,"Advance")))) -> Last Minute | K8: 17348
A9: BK1007 | B9: FLT10078 | C9: RT1 | D9: AL105 | E9: Vistara | F9: Economy | G9: 1 | H9: 26 | I9: 2 | J9: =IF(I9<=7,"Last Minute",IF(I9<=15,"Short Notice",IF(I9<=30,"Moderate",IF(I9>=31,"Advance")))) -> Last Minute | K9: 15353
A10: BK1008 | B10: FLT10079 | C10: RT1 | D10: AL103 | E10: Indigo | F10: Economy | G10: 1 | H10: 4.17 | I10: 38 | J10: =IF(I10<=7,"Last Minute",IF(I10<=15,"Short Notice",IF(I10<=30,"Moderate",IF(I10>=31,"Advance")))) -> Advance | K10: 3054
A11: BK1009 | B11: FLT10081 | C11: RT1 | D11: AL103 | E11: Indigo | F11: Economy | G11: 1 | H11: 5.08 | I11: 39 | J11: =IF(I11<=7,"Last Minute",IF(I11<=15,"Short Notice",IF(I11<=30,"Moderate",IF(I11>=31,"Advance")))) -> Advance | K11: 3631
A12: BK1010 | B12: FLT10082 | C12: RT1 | D12: AL101 | E12: Air_India | F12: Economy | G12: 1 | H12: 29.33 | J12: =IF(I12<=7,"Last Minute",IF(I12<=15,"Short Notice",IF(I12<=30,"Moderate",IF(I12>=31,"Advance")))) -> Last Minute | K12: 16245
A13: BK1011 | B13: FLT10083 | C13: RT1 | D13: AL105 | E13: Vistara | F13: Economy | G13: 1 | H13: 4.42 | I13: 46 | J13: =IF(I13<=7,"Last Minute",IF(I13<=15,"Short Notice",IF(I13<=30,"Moderate",IF(I13>=31,"Advance")))) -> Advance | K13: 4381
A14: BK1012 | B14: FLT10084 | C14: RT1 | D14: AL105 | E14: Vistara | F14: Economy | G14: 1 | H14: 17 | I14: 22 | J14: =IF(I14<=7,"Last Minute",IF(I14<=15,"Short Notice",IF(I14<=30,"Moderate",IF(I14>=31,"Advance")))) -> Moderate | K14: 7575
A15: BK1013 | B15: FLT10086 | C15: RT1 | D15: AL101 | E15: Air_India | F15: Economy | G15: 1 | H15: 27.17 | I15: 1 | J15: =IF(I15<=7,"Last Minute",IF(I15<=15,"Short Notice",IF(I15<=30,"Moderate",IF(I15>=31,"Advance")))) -> Last Minute | K15: 16455
A16: BK1014 | B16: FLT10109 | C16: RT1 | D16: AL105 | E16: Vistara | F16: Economy | G16: 1 | H16: 16 | I16: 27 | J16: =IF(I16<=7,"Last Minute",IF(I16<=15,"Short Notice",IF(I16<=30,"Moderate",IF(I16>=31,"Advance")))) -> Moderate | K16: 7575
A17: BK1015 | B17: FLT10131 | C17: RT1 | D17: AL101 | E17: Air_India | F17: Economy | G17: 1 | H17: 3.5 | I17: 37 | J17: =IF(I17<=7,"Last Minute",IF(I17<=15,"Short Notice",IF(I17<=30,"Moderate",IF(I17>=31,"Advance")))) -> Advance | K17: 2476
A18: BK1016 | B18: FLT10140 | C18: RT1 | D18: AL101 | E18: Air_India | F18: Economy | G18: 1 | H18: 6.67 | I18: 36 | J18: =IF(I18<=7,"Last Minute",IF(I18<=15,"Short Notice",IF(I18<=30,"Moderate",IF(I18>=31,"Advance")))) -> Advance | K18: 3831
A19: BK1017 | B19: FLT10145 | C19: RT1 | D19: AL105 | E19: Vistara | F19: Business | G19: 1 | H19: 8.25 | J19: =IF(I19<=7,"Last Minute",IF(I19<=15,"Short Notice",IF(I19<=30,"Moderate",IF(I19>=31,"Advance")))) -> Last Minute | K19: 41281
A20: BK1018 | B20: FLT10153 | C20: RT1 | D20: AL101 | E20: Air_India | F20: Business | G20: 1 | H20: 21.42 | I20: 15 | J20: =IF(I20<=7,"Last Minute",IF(I20<=15,"Short Notice",IF(I20<=30,"Moderate",IF(I20>=31,"Advance")))) -> Short Notice | K20: 47217
A21: BK1019 | B21: FLT10155 | C21: RT1 | D21: AL102 | E21: Go_First | F21: Economy | G21: 1 | H21: 7.75 | I21: 2 | J21: =IF(I21<=7,"Last Minute",IF(I21<=15,"Short Notice",IF(I21<=30,"Moderate",IF(I21>=31,"Advance")))) -> Last Minute | K21: 13321
A22: BK1020 | B22: FLT10185 | C22: RT1 | D22: AL101 | E22: Air_India | F22: Business | G22: 1 | H22: 23.83 | I22: 30 | J22: =IF(I22<=7,"Last Minute",IF(I22<=15,"Short Notice",IF(I22<=30,"Moderate",IF(I22>=31,"Advance")))) -> Moderate | K22: 53164
A23: BK1021 | B23: FLT10204 | C23: RT1 | D23: AL101 | E23: Air_India | F23: Business | G23: 1 | H23: 20.58 | I23: 9 | J23: =IF(I23<=7,"Last Minute",IF(I23<=15,"Short Notice",IF(I23<=30,"Moderate",IF(I23>=31,"Advance")))) -> Short Notice | K23: 32646
A24: BK1022 | B24: FLT10222 | C24: RT1 | D24: AL105 | E24: Vistara | F24: Economy | G24: 1 | H24: 16.33 | I24: 45 | J24: =IF(I24<=7,"Last Minute",IF(I24<=15,"Short Notice",IF(I24<=30,"Moderate",IF(I24>=31,"Advance")))) -> Advance | K24: 5857
A25: BK1023 | B25: FLT10229 | C25: RT1 | D25: AL105 | E25: Vistara | F25: Economy | G25: 1 | H25: 13.08 | I25: 44 | J25: =IF(I25<=7,"Last Minute",IF(I25<=15,"Short Notice",IF(I25<=30,"Moderate",IF(I25>=31,"Advance")))) -> Advance | K25: 5355
A26: BK1024 | B26: FLT10235 | C26: RT1 | D26: AL101 | E26: Air_India | F26: Economy | G26: 1 | H26: 11 | I26: 4 | J26: =IF(I26<=7,"Last Minute",IF(I26<=15,"Short Notice",IF(I26<=30,"Moderate",IF(I26>=31,"Advance")))) -> Last Minute | K26: 15825
A27: BK1025 | B27: FLT10255 | C27: RT1 | D27: AL105 | E27: Vistara | F27: Business | G27: 1 | H27: 6.5 | I27: 5 | J27: =IF(I27<=7,"Last Minute",IF(I27<=15,"Short Notice",IF(I27<=30,"Moderate",IF(I27>=31,"Advance")))) -> Last Minute | K27: 7336
A28: BK1026 | B28: FLT10265 | C28: RT1 | D28: AL101 | E28: Air_India | F28: Business | G28: 1 | H28: 8.58 | J28: =IF(I28<=7,"Last Minute",IF(I28<=15,"Short Notice",IF(I28<=30,"Moderate",IF(I28>=31,"Advance")))) -> Last Minute | K28: 49896
A29: BK1027 | B29: FLT10271 | C29: RT1 | D29: AL103 | E29: Indigo | F29: Economy | G29: 0 | H29: 2.17 | I29: 39 | J29: =IF(I29<=7,"Last Minute",IF(I29<=15,"Short Notice",IF(I29<=30,"Moderate",IF(I29>=31,"Advance")))) -> Advance | K29: 2410
A30: BK1028 | B30: FLT10275 | C30: RT1 | D30: AL103 | E30: Indigo | F30: Economy | G30: 1 | H30: 4.92 | J30: =IF(I30<=7,"Last Minute",IF(I30<=15,"Short Notice",IF(I30<=30,"Moderate",IF(I30>=31,"Advance")))) -> Last Minute | K30: 3911
A31: BK1029 | B31: FLT10305 | C31: RT1 | D31: AL102 | E31: Go_First | F31: Economy | G31: 1 | H31: 9.33 | I31: 36 | J31: =IF(I31<=7,"Last Minute",IF(I31<=15,"Short Notice",IF(I31<=30,"Moderate",IF(I31>=31,"Advance")))) -> Advance | K31: 3330
A32: BK1030 | B32: FLT10365 | C32: RT1 | D32: AL103 | E32: Indigo | F32: Economy | G32: 0 | H32: 2.17 | I32: 27 | J32: =IF(I32<=7,"Last Minute",IF(I32<=15,"Short Notice",IF(I32<=30,"Moderate",IF(I32>=31,"Advance")))) -> Moderate | K32: 2410
A33: BK1031 | B33: FLT10395 | C33: RT1 | D33: AL103 | E33: Indigo | F33: Economy | G33: 1 | H33: 10 | I33: 44 | J33: =IF(I33<=7,"Last Minute",IF(I33<=15,"Short Notice",IF(I33<=30,"Moderate",IF(I33>=31,"Advance")))) -> Advance | K33: 4373
A34: BK1032 | B34: FLT10400 | C34: RT1 | D34: AL102 | E34: Go_First | F34: Economy | G34: 1 | H34: 12.75 | I34: 44 | J34: =IF(I34<=7,"Last Minute",IF(I34<=15,"Short Notice",IF(I34<=30,"Moderate",IF(I34>=31,"Advance")))) -> Advance | K34: 6146
A35: BK1033 | B35: FLT10404 | C35: RT1 | D35: AL103 | E35: Indigo | F35: Economy | G35: 0 | H35: 2.17 | I35: 46 | J35: =IF(I35<=7,"Last Minute",IF(I35<=15,"Short Notice",IF(I35<=30,"Moderate",IF(I35>=31,"Advance")))) -> Advance | K35: 2410
A36: BK1034 | B36: FLT10408 | C36: RT1 | D36: AL102 | E36: Go_First | F36: Economy | G36: 0 | H36: 2.25 | I36: 46 | J36: =IF(I36<=7,"Last Minute",IF(I36<=15,"Short Notice",IF(I36<=30,"Moderate",IF(I36>=31,"Advance")))) -> Advance | K36: 2410
A37: BK1035 | B37: FLT10429 | C37: RT1 | D37: AL102 | E37: Go_First | F37: Economy | G37: 1 | H37: 5.92 | I37: 46 | J37: =IF(I37<=7,"Last Minute",IF(I37<=15,"Short Notice",IF(I37<=30,"Moderate",IF(I37>=31,"Advance")))) -> Advance | K37: 3330
A38: BK1036 | B38: FLT10431 | C38: RT1 | D38: AL103 | E38: Indigo | F38: Economy | G38: 1 | H38: 7.5 | J38: =IF(I38<=7,"Last Minute",IF(I38<=15,"Short Notice",IF(I38<=30,"Moderate",IF(I38>=31,"Advance")))) -> Last Minute | K38: 2381
A39: BK1037 | B39: FLT10508 | C39: RT1 | D39: AL103 | E39: Indigo | F39: Economy | G39: 0 | H39: 2.08 | I39: 46 | J39: =IF(I39<=7,"Last Minute",IF(I39<=15,"Short Notice",IF(I39<=30,"Moderate",IF(I39>=31,"Advance")))) -> Advance | K39: 3159
A40: BK1038 | B40: FLT10522 | C40: RT1 | D40: AL102 | E40: Go_First | F40: Economy | G40: 1 | H40: 4.92 | I40: 47 | J40: =IF(I40<=7,"Last Minute",IF(I40<=15,"Short Notice",IF(I40<=30,"Moderate",IF(I40>=31,"Advance")))) -> Advance | K40: 4399
...

Sheet Flights
A1: Flight_Id | B1: Airline_Id | C1: Flight_Code | D1: Route_Id | E1: Source_City | F1: Destination_City | G1: Departure_Time | H1: Arrival_Time | I1: Stops | J1: Duration | K1: Route
A2: FLT22651 | B2: AL105 | C2: UK-811 | D2: RT1 | E2: Delhi | F2: Mumbai | G2: Morning | H2: Night | I2: 1 | J2: 14.33 | K2: =CONCATENATE(E2," -> ",F2) -> Delhi -> Mumbai
A3: FLT10081 | B3: AL103 | C3: 6E-2102 | D3: RT1 | E3: Delhi | F3: Mumbai | G3: Morning | H3: Afternoon | I3: 1 | J3: 5.08 | K3: =CONCATENATE(E3," -> ",F3) -> Delhi -> Mumbai
A4: FLT10140 | B4: AL101 | C4: AI-544 | D4: RT1 | E4: Delhi | F4: Mumbai | G4: Evening | H4: Night | I4: 1 | J4: 6.67 | K4: =CONCATENATE(E4," -> ",F4) -> Delhi -> Mumbai
A5: FLT10079 | B5: AL103 | C5: 6e-184 | D5: RT1 | E5: Delhi | F5: Mumbai | G5: Morning | H5: Afternoon | I5: 1 | J5: 4.17 | K5: =CONCATENATE(E5," -> ",F5) -> Delhi -> Mumbai
A6: FLT10271 | B6: AL103 | C6: 6E-2137 | D6: RT1 | E6: Delhi | F6: Mumbai | G6: Night | H6: Night | I6: 0 | J6: 2.17 | K6: =CONCATENATE(E6," -> ",F6) -> Delhi -> Mumbai
A7: FLT10229 | B7: AL105 | C7: UK-835 | D7: RT1 | E7: Delhi | F7: Mumbai | G7: Evening | H7: Morning | I7: 1 | J7: 13.08 | K7: =CONCATENATE(E7," -> ",F7) -> Delhi -> Mumbai
A8: FLT10429 | B8: AL102 | C8: G8-713 | D8: RT1 | E8: Delhi | F8: Mumbai | G8: Night | H8: Night | I8: 1 | J8: 5.92 | K8: =CONCATENATE(E8," -> ",F8) -> Delhi -> Mumbai
A9: FLT10400 | B9: AL102 | C9: G8-119 | D9: RT1 | E9: Delhi | F9: Mumbai | G9: Evening | H9: Morning | I9: 1 | J9: 12.75 | K9: =CONCATENATE(E9," -> ",F9) -> Delhi -> Mumbai
A10: FLT10082 | B10: AL101 | C10: AI-801 | D10: RT1 | E10: Delhi | F10: Mumbai | G10: Evening | H10: Night | I10: 1 | J10: 29.33 | K10: =CONCATENATE(E10," -> ",F10) -> Delhi -> Mumbai
A11: FLT10305 | B11: AL102 | C11: G8-717 | D11: RT1 | E11: Delhi | F11: Mumbai | G11: Evening | H11: Night | I11: 1 | J11: 9.33 | K11: =CONCATENATE(E11," -> ",F11) -> Delhi -> Mumbai
A12: FLT10185 | B12: AL101 | C12: AI-504 | D12: RT1 | E12: Delhi | F12: Mumbai | G12: Night | H12: Night | I12: 1 | J12: 23.83 | K12: =CONCATENATE(E12," -> ",F12) -> Delhi -> Mumbai
A13: FLT10010 | B13: AL102 | C13: G8-392 | D13: RT1 | E13: Delhi | F13: Mumbai | G13: Afternoon | H13: Evening | I13: 0 | J13: 2.25 | K13: =CONCATENATE(E13," -> ",F13) -> Delhi -> Mumbai
A14: FLT10083 | B14: AL105 | C14: UK-637 | D14: RT1 | E14: Delhi | F14: Mumbai | G14: Evening | H14: Night | I14: 1 | J14: 4.42 | K14: =CONCATENATE(E14," -> ",F14) -> Delhi -> Mumbai
A15: FLT10222 | B15: AL105 | C15: UK-879 | D15: RT1 | E15: Delhi | F15: Mumbai | G15: Evening | H15: Morning | I15: 1 | J15: 16.33 | K15: =CONCATENATE(E15," -> ",F15) -> Delhi -> Mumbai
A16: FLT10265 | B16: AL101 | C16: AI-512 | D16: RT1 | E16: Delhi | F16: Mumbai | G16: Afternoon | H16: Night | I16: 1 | J16: 8.58 | K16: =CONCATENATE(E16," -> ",F16) -> Delhi -> Mumbai
A17: FLT10084 | B17: AL105 | C17: UK-747 | D17: RT1 | E17: Delhi | F17: Mumbai | G17: Morning | H17: Night | I17: 1 | J17: 17 | K17: =CONCATENATE(E17," -> ",F17) -> Delhi -> Mumbai
... A46: FLT14639 | B46: AL103 | C46: 6E-6809 | D46: RT10 | E46: Mumbai | F46: Chennai | G46: Evening | H46: Night | I46: 1 | J46: 4.75 | K46: =CONCATENATE(E46," -> ",F46) -> Mumbai -> Chennai
A47: FLT14821 | B47: AL105 | C47: UK-849 | D47: RT10 | E47: Mumbai | F47: Chennai | G47: Evening | H47: Morning | I47: 2+ | J47: 16.42 | K47: =CONCATENATE(E47," -> ",F47) -> Mumbai -> Chennai
A48: FLT14658 | B48: AL105 | C48: UK-960 | D48: RT10 | E48: Mumbai | F48: Chennai | G48: Morning | H48: Night | I48: 1 | J48: 8.33 | K48: =CONCATENATE(E48," -> ",F48) -> Mumbai -> Chennai
A49: FLT14701 | B49: AL101 | C49: AI-806 | D49: RT10 | E49: Mumbai | F49: Chennai | G49: Morning | H49: Night | I49: 1 | J49: 13.33 | K49: =CONCATENATE(E49," -> ",F49) -> Mumbai -> Chennai
A50: FLT14887 | B50: AL101 | C50: AI-867 | D50: RT10 | E50: Mumbai | F50: Chennai | G50: Night | H50: Night | I50: 1 | J50: 25.08 | K50: =CONCATENATE(E50," -> ",F50) -> Mumbai -> Chennai
A51: FLT14708 | B51: AL101 | C51: AI-809 | D51: RT10 | E51: Mumbai | F51: Chennai | G51: Morning | H51: Night | I51: 1 | J51: 13.58 | K51: =CONCATENATE(E51," -> ",F51) -> Mumbai -> Chennai
A52: FLT14815 | B52: AL100 | C52: I5-942 | D52: RT10 | E52: Mumbai | F52: Chennai | G52: Afternoon | H52: Evening | I52: 1 | J52: 4.33 | K52: =CONCATENATE(E52," -> ",F52) -> Mumbai -> Chennai
A53: FLT14621 | B53: AL104 | C53: SG-251 | D53: RT10 | E53: Mumbai | F53: Chennai | G53: Night | H53: Night | I53: 0 | J53: 1.83 | K53: =CONCATENATE(E53," -> ",F53) -> Mumbai -> Chennai
A54: FLT14735 | B54: AL105 | C54: UK-655 | D54: RT10 | E54: Mumbai | F54: Chennai | G54: Morning | H54: Evening | I54: 2+ | J54: 28.83 | K54: =CONCATENATE(E54," -> ",F54) -> Mumbai -> Chennai
A55: FLT14637 | B55: AL105 | C55: UK-996 | D55: RT10 | E55: Mumbai | F55: Chennai | G55: Evening | H55: Morning | I55: 1 | J55: 15.42 | K55: =CONCATENATE(E55," -> ",F55) -> Mumbai -> Chennai
A56: FLT14737 | B56: AL101 | C56: AI-651 | D56: RT10 | E56: Mumbai | F56: Chennai | G56: Morning | H56: Evening | I56: 2+ | J56: 33.83 | K56: =CONCATENATE(E56," -> ",F56) -> Mumbai -> Chennai
A57: FLT14860 | B57: AL101 | C57: AI-806 | D57: RT10 | E57: Mumbai | F57: Chennai | G57: Morning | H57: Evening | I57: 2+ | J57: 11 | K57: =CONCATENATE(E57," -> ",F57) -> Mumbai -> Chennai
A58: FLT14582 | B58: AL103 | C58: 6E-5208 | D58: RT10 | E58: Mumbai | F58: Chennai | G58: Evening | H58: Night | I58: 1 | J58: 7.25 | K58: =CONCATENATE(E58," -> ",F58) -> Mumbai -> Chennai
A59: FLT14813 | B59: AL101 | C59: AI-673 | D59: RT10 | E59: Mumbai | F59: Chennai | G59: Morning | H59: Evening | I59: 1 | J59: 11.75 | K59: =CONCATENATE(E59," -> ",F59) -> Mumbai -> Chennai
A60: FLT14917 | B60: AL103 | C60: 6E-6094 | D60: RT10 | E60: Mumbai | F60: Chennai | G60: Night | H60: Night | I60: 0 | J60: 2.08 | K60: =CONCATENATE(E60," -> ",F60) -> Mumbai -> Chennai
A61: FLT14683 | B61: AL105 | C61: UK-928 | D61: RT10 | E61: Mumbai | F61: Chennai | G61: Morning | H61: Night | I61: 1 | J61: 13.25 | K61: =CONCATENATE(E61," -> ",F61) -> Mumbai -> Chennai
A62: FLT14591 | B62: AL101 | C62: AI-442 | D62: RT10 | E62: Mumbai | F62: Chennai | G62: Afternoon | H62: Evening | I62: 1 | J62: 27.42 | K62: =CONCATENATE(E62," -> ",F62) -> Mumbai -> Chennai
A63: FLT14762 | B63: AL105 | C63: UK-930 | D63: RT10 | E63: Mumbai | F63: Chennai | G63: Morning | H63: Night | I63: 1 | J63: 15.25 | K63: =CONCATENATE(E63," -> ",F63) -> Mumbai -> Chennai
A64: FLT14654 | B64: AL105 | C64: UK-851 | D64: RT10 | E64: Mumbai | F64: Chennai | G64: Morning | H64: Night | I64: 2+ | J64: 37.25 | K64: =CONCATENATE(E64," -> ",F64) -> Mumbai -> Chennai
A65: FLT14819 | B65: AL103 | C65: 6E-5396 | D65: RT10 | E65: Mumbai | F65: Chennai | G65: Morning | H65: Evening | I65: 1 | J65: 7.5 | K65: =CONCATENATE(E65," -> ",F65) -> Mumbai -> Chennai
A66: FLT14837 | B66: AL102 | C66: G8-244 | D66: RT10 | E66: Mumbai | F66: Chennai | G66: Evening | H66: Night | I66: 1 | J66: 7 | K66: =CONCATENATE(E66," -> ",F66) -> Mumbai -> Chennai
A67: FLT14719 | B67: AL105 | C67: UK-994 | D67: RT10 | E67: Mumbai | F67: Chennai | G67: Morning | H67: Morning | I67: 1 | J67: 23.5 | K67: =CONCATENATE(E67," -> ",F67) -> Mumbai -> Chennai
A68: FLT14807 | B68: AL105 | C68: UK-986 | D68: RT10 | E68: Mumbai | F68: Chennai | G68: Night | H68: Night | I68: 1 | J68: 24 | K68: =CONCATENATE(E68," -> ",F68) -> Mumbai -> Chennai
...

Sheet Routes
A1: Route_Id | B1: Source_City | C1: Destination_City | D1: Total_Bookings | E1: Unique_Flights | F1: Airlines_Serving | G1: Avg_Price | H1: Min_Price | I1: Max_Price | J1: Avg_Duration_Hrs | K1: Economy_Bookings | L1: Business_Bookings
A2: RT1 | B2: Delhi | C2: Mumbai | D2: =COUNTIF(Flights!D:D,A2) -> 40 | E2: {=COUNTA(UNIQUE(_xlws.FILTER(Flights!A:A,(Flights!E:E=B2)*(Flights!F:F=C2))))} -> 1 | F2: {=COUNTA(UNIQUE(_xlws.FILTER(Flights!B:B,(Flights!E:E=B2)*(Flights!F:F=C2)*(Flights!B:B<>""))))} -> 1 | G2: =AVERAGEIF(Bookings!C:C,A2,Bookings!K:K) -> 15969.15 | H2: =MINIFS(Bookings!K:K,Bookings!C:C,A2) -> 2381 | I2: =MAXIFS(Bookings!K:K,Bookings!C:C,A2) -> 71056 | J2: =AVERAGEIFS(Flights!J:J,Flights!D:D,A2) -> 10.9085 | K2: =COUNTIFS(Bookings!F:F,"Economy",Bookings!C:C,A2) -> 30 | L2: =COUNTIFS(Bookings!F:F,"Business",Bookings!C:C,A2) -> 10
A3: RT2 | B3: Delhi | C3: Bengaluru | D3: =COUNTIF(Flights!D:D,A3) -> 40 | E3: {=COUNTA(UNIQUE(_xlws.FILTER(Flights!A:A,(Flights!E:E=B3)*(Flights!F:F=C3))))} -> 1 | F3: {=COUNTA(UNIQUE(_xlws.FILTER(Flights!B:B,(Flights!E:E=B3)*(Flights!F:F=C3)*(Flights!B:B<>""))))} -> 1 | G3: =AVERAGEIF(Bookings!C:C,A3,Bookings!K:K) -> 13093.1 | H3: =MINIFS(Bookings!K:K,Bookings!C:C,A3) -> 3090 | I3: =MAXIFS(Bookings!K:K,Bookings!C:C,A3) -> 54777 | J3: =AVERAGEIFS(Flights!J:J,Flights!D:D,A3) -> 11.6415 | K3: =COUNTIFS(Bookings!F:F,"Economy",Bookings!C:C,A3) -> 34 | L3: =COUNTIFS(Bookings!F:F,"Business",Bookings!C:C,A3) -> 6
A4: RT3 | B4: Delhi | C4: Kolkata | D4: =COUNTIF(Flights!D:D,A4) -> 40 | E4: {=COUNTA(UNIQUE(_xlws.FILTER(Flights!A:A,(Flights!E:E=B4)*(Flights!F:F=C4))))} -> 1 | F4: {=COUNTA(UNIQUE(_xlws.FILTER(Flights!B:B,(Flights!E:E=B4)*(Flights!F:F=C4)*(Flights!B:B<>""))))} -> 1 | G4: =AVERAGEIF(Bookings!C:C,A4,Bookings!K:K) -> 13356.975 | H4: =MINIFS(Bookings!K:K,Bookings!C:C,A4) -> 2482 | I4: =MAXIFS(Bookings!K:K,Bookings!C:C,A4) -> 53209 | J4: =AVERAGEIFS(Flights!J:J,Flights!D:D,A4) -> 14.379 | K4: =COUNTIFS(Bookings!F:F,"Economy",Bookings!C:C,A4) -> 34 | L4: =COUNTIFS(Bookings!F:F,"Business",Bookings!C:C,A4) -> 6
A5: RT4 | B5: Delhi | C5: Hyderabad | D5: =COUNTIF(Flights!D:D,A5) -> 40 | E5: {=COUNTA(UNIQUE(_xlws.FILTER(Flights!A:A,(Flights!E:E=B5)*(Flights!F:F=C5))))} -> 1 | F5: {=COUNTA(UNIQUE(_xlws.FILTER(Flights!B:B,(Flights!E:E=B5)*(Flights!F:F=C5)*(Flights!B:B<>""))))} -> 1 | G5: =AVERAGEIF(Bookings!C:C,A5,Bookings!K:K) -> 12376.25 | H5: =MINIFS(Bookings!K:K,Bookings!C:C,A5) -> 2050 | I5: =MAXIFS(Bookings!K:K,Bookings!C:C,A5) -> 61889 | J5: =AVERAGEIFS(Flights!J:J,Flights!D:D,A5) -> 12.65425 | K5: =COUNTIFS(Bookings!F:F,"Economy",Bookings!C:C,A5) -> 33 | L5: =COUNTIFS(Bookings!F:F,"Business",Bookings!C:C,A5) -> 7
A6: RT5 | B6: Delhi | C6: Chennai | D6: =COUNTIF(Flights!D:D,A6) -> 40 | E6: {=COUNTA(UNIQUE(_xlws.FILTER(Flights!A:A,(Flights!E:E=B6)*(Flights!F:F=C6))))} -> 1 | F6: {=COUNTA(UNIQUE(_xlws.FILTER(Flights!B:B,(Flights!E:E=B6)*(Flights!F:F=C6)*(Flights!B:B<>""))))} -> 1 | G6: =AVERAGEIF(Bookings!C:C,A6,Bookings!K:K) -> 19602.975 | H6: =MINIFS(Bookings!K:K,Bookings!C:C,A6) -> 1998 | I6: =MAXIFS(Bookings!K:K,Bookings!C:C,A6) -> 70323 | J6: =AVERAGEIFS(Flights!J:J,Flights!D:D,A6) -> 15.8045 | K6: =COUNTIFS(Bookings!F:F,"Economy",Bookings!C:C,A6) -> 29 | L6: =COUNTIFS(Bookings!F:F,"Business",Bookings!C:C,A6) -> 11
A7: RT6 | B7: Mumbai | C7: Delhi | D7: =COUNTIF(Flights!D:D,A7) -> 40 | E7: {=COUNTA(UNIQUE(_xlws.FILTER(Flights!A:A,(Flights!E:E=B7)*(Flights!F:F=C7))))} -> 1 | F7: {=COUNTA(UNIQUE(_xlws.FILTER(Flights!B:B,(Flights!E:E=B7)*(Flights!F:F=C7)*(Flights!B:B<>""))))} -> 1 | G7: =AVERAGEIF(Bookings!C:C,A7,Bookings!K:K) -> 14808.775 | H7: =MINIFS(Bookings!K:K,Bookings!C:C,A7) -> 2336 | I7: =MAXIFS(Bookings!K:K,Bookings!C:C,A7) -> 59964 | J7: =AVERAGEIFS(Flights!J:J,Flights!D:D,A7) -> 10.546 | K7: =COUNTIFS(Bookings!F:F,"Economy",Bookings!C:C,A7) -> 32 | L7: =COUNTIFS(Bookings!F:F,"Business",Bookings!C:C,A7) -> 8
A8: RT7 | B8: Mumbai | C8: Bengaluru | D8: =COUNTIF(Flights!D:D,A8) -> 40 | E8: {=COUNTA(UNIQUE(_xlws.FILTER(Flights!A:A,(Flights!E:E=B8)*(Flights!F:F=C8))))} -> 1 | F8: {=COUNTA(UNIQUE(_xlws.FILTER(Flights!B:B,(Flights!E:E=B8)*(Flights!F:F=C8)*(Flights!B:B<>""))))} -> 1 | G8: =AVERAGEIF(Bookings!C:C,A8,Bookings!K:K) -> 12374.875 | H8: =MINIFS(Bookings!K:K,Bookings!C:C,A8) -> 2074 | I8: =MAXIFS(Bookings!K:K,Bookings!C:C,A8) -> 74880 | J8: =AVERAGEIFS(Flights!J:J,Flights!D:D,A8) -> 13.406 | K8: =COUNTIFS(Bookings!F:F,"Economy",Bookings!C:C,A8) -> 37 | L8: =COUNTIFS(Bookings!F:F,"Business",Bookings!C:C,A8) -> 3
A9: RT8 | B9: Mumbai | C9: Kolkata | D9: =COUNTIF(Flights!D:D,A9) -> 40 | E9: {=COUNTA(UNIQUE(_xlws.FILTER(Flights!A:A,(Flights!E:E=B9)*(Flights!F:F=C9))))} -> 1 | F9: {=COUNTA(UNIQUE(_xlws.FILTER(Flights!B:B,(Flights!E:E=B9)*(Flights!F:F=C9)*(Flights!B:B<>""))))} -> 1 | G9: =AVERAGEIF(Bookings!C:C,A9,Bookings!K:K) -> 12740.025 | H9: =MINIFS(Bookings!K:K,Bookings!C:C,A9) -> 2835 | I9: =MAXIFS(Bookings!K:K,Bookings!C:C,A9) -> 64285 | J9: =AVERAGEIFS(Flights!J:J,Flights!D:D,A9) -> 14.77875 | K9: =COUNTIFS(Bookings!F:F,"Economy",Bookings!C:C,A9) -> 36 | L9: =COUNTIFS(Bookings!F:F,"Business",Bookings!C:C,A9) -> 4
A10: RT9 | B10: Mumbai | C10: Hyderabad | D10: =COUNTIF(Flights!D:D,A10) -> 40 | E10: {=COUNTA(UNIQUE(_xlws.FILTER(Flights!A:A,(Flights!E:E=B10)*(Flights!F:F=C10))))} -> 1 | F10: {=COUNTA(UNIQUE(_xlws.FILTER(Flights!B:B,(Flights!E:E=B10)*(Flights!F:F=C10)*(Flights!B:B<>""))))} -> 1 | G10: =AVERAGEIF(Bookings!C:C,A10,Bookings!K:K) -> 21092.8 | H10: =MINIFS(Bookings!K:K,Bookings!C:C,A10) -> 2111 | I10: =MAXIFS(Bookings!K:K,Bookings!C:C,A10) -> 60365 | J10: =AVERAGEIFS(Flights!J:J,Flights!D:D,A10) -> 16.1605 | K10: =COUNTIFS(Bookings!F:F,"Economy",Bookings!C:C,A10) -> 26 | L10: =COUNTIFS(Bookings!F:F,"Business",Bookings!C:C,A10) -> 14
A11: RT10 | B11: Mumbai | C11: Chennai | D11: =COUNTIF(Flights!D:D,A11) -> 40 | E11: {=COUNTA(UNIQUE(_xlws.FILTER(Flights!A:A,(Flights!E:E=B11)*(Flights!F:F=C11))))} -> 1 | F11: {=COUNTA(UNIQUE(_xlws.FILTER(Flights!B:B,(Flights!E:E=B11)*(Flights!F:F=C11)*(Flights!B:B<>""))))} -> 1 | G11: =AVERAGEIF(Bookings!C:C,A11,Bookings!K:K) -> 17122.75 | H11: =MINIFS(Bookings!K:K,Bookings!C:C,A11) -> 1890 | I11: =MAXIFS(Bookings!K:K,Bookings!C:C,A11) -> 69885 | J11: =AVERAGEIFS(Flights!J:J,Flights!D:D,A11) -> 15.9765 | K11: =COUNTIFS(Bookings!F:F,"Economy",Bookings!C:C,A11) -> 33 | L11: =COUNTIFS(Bookings!F:F,"Business",Bookings!C:C,A11) -> 7
A12: RT11 | B12: Bengaluru | C12: Delhi | D12: =COUNTIF(Flights!D:D,A12) -> 40 | E12: {=COUNTA(UNIQUE(_xlws.FILTER(Flights!A:A,(Flights!E:E=B12)*(Flights!F:F=C12))))} -> 1 | F12: {=COUNTA(UNIQUE(_xlws.FILTER(Flights!B:B,(Flights!E:E=B12)*(Flights!F:F=C12)*(Flights!B:B<>""))))} -> 1 | G12: =AVERAGEIF(Bookings!C:C,A12,Bookings!K:K) -> 11995.55 | H12: =MINIFS(Bookings!K:K,Bookings!C:C,A12) -> 2723 | I12: =MAXIFS(Bookings!K:K,Bookings!C:C,A12) -> 66411 | J12: =AVERAGEIFS(Flights!J:J,Flights!D:D,A12) -> 11.719 | K12: =COUNTIFS(Bookings!F:F,"Economy",Bookings!C:C,A12) -> 34 | L12: =COUNTIFS(Bookings!F:F,"Business",Bookings!C:C,A12) -> 6
A13: RT12 | B13: Bengaluru | C13: Mumbai | D13: =COUNTIF(Flights!D:D,A13) -> 40 | E13: {=COUNTA(UNIQUE(_xlws.FILTER(Flights!A:A,(Flights!E:E=B13)*(Flights!F:F=C13))))} -> 1 | F13: {=COUNTA(UNIQUE(_xlws.FILTER(Flights!B:B,(Flights!E:E=B13)*(Flights!F:F=C13)*(Flights!B:B<>""))))} -> 1 | G13: =AVERAGEIF(Bookings!C:C,A13,Bookings!K:K) -> 19002.775 | H13: =MINIFS(Bookings!K:K,Bookings!C:C,A13) -> 3012 | I13: =MAXIFS(Bookings!K:K,Bookings!C:C,A13) -> 83916 | J13: =AVERAGEIFS(Flights!J:J,Flights!D:D,A13) -> 13.833 | K13: =COUNTIFS(Bookings!F:F,"Economy",Bookings!C:C,A13) -> 31 | L13: =COUNTIFS(Bookings!F:F,"Business",Bookings!C:C,A13) -> 9
... A31: RT30 | B31: Chennai | C31: Hyderabad | D31: =COUNTIF(Flights!D:D,A31) -> 40 | E31: {=COUNTA(UNIQUE(_xlws.FILTER(Flights!A:A,(Flights!E:E=B31)*(Flights!F:F=C31))))} -> 1 | F31: {=COUNTA(UNIQUE(_xlws.FILTER(Flights!B:B,(Flights!E:E=B31)*(Flights!F:F=C31)*(Flights!B:B<>""))))} -> 1 | G31: =AVERAGEIF(Bookings!C:C,A31,Bookings!K:K) -> 13911.7 | H31: =MINIFS(Bookings!K:K,Bookings!C:C,A31) -> 1105 | I31: =MAXIFS(Bookings!K:K,Bookings!C:C,A31) -> 87118 | J31: =AVERAGEIFS(Flights!J:J,Flights!D:D,A31) -> 13.09225 | K31: =COUNTIFS(Bookings!F:F,"Economy",Bookings!C:C,A31) -> 34 | L31: =COUNTIFS(Bookings!F:F,"Business",Bookings!C:C,A31) -> 6

Sheet Analysis
A1: Booking_Id | B1: Flight_Id | C1: Route_Id | D1: Airline_Id | E1: Airline_Name | F1: Class | G1: Source_City | H1: Destination_City | I1: Stops | J1: Duration_Hrs | K1: Duration_Category | L1: Price | M1: Price_Category | N1: Days_Left | O1: Booking_Window | P1: Routes
A2: BK1000 | B2: FLT10002 | C2: RT1 | D2: AL100 | E2: {=IFERROR(INDEX(Airlines!$B:$B,MATCH(D2,Airlines!$A:$A,0)),"")} -> AirAsia | F2: =VLOOKUP(A2,Bookings!$A:$F,6,FALSE()) -> Economy | G2: {=IFERROR(INDEX(Flights!$E:$E,MATCH(B2,Flights!$A:$A,0)),"")} -> Delhi | H2: =VLOOKUP(B2,Flights!A:H,6,FALSE()) -> Mumbai | I2: {=IFERROR(INDEX(Bookings!$G:$G,MATCH(B2,Bookings!$B:$B,0)),"")} -> 0 | J2: =VLOOKUP(B2,Bookings!B:H,7,FALSE()) -> 2.17 | K2: =IF(J2<=4,"Short",IF(J2<=10,"Medium",IF(J2>10,"Long"))) -> Short | L2: {=IFERROR(INDEX(Bookings!$K:$K,MATCH(A2,Bookings!$A:$A,0)),"")} -> 5956 | M2: =IF(L2="","",IF(L2<=4631,"Low",IF(L2<=15800,"Medium","High"))) -> Medium | N2: {=IFERROR(INDEX(Bookings!$I:$I,MATCH(A2,Bookings!$A:$A,0)),"")} -> 14 | O2: =IF(N2<=7,"Last Minute",IF(N2<=15,"Short Notice",IF(N2<=30,"Moderate",IF(N2>=31,"Advance")))) -> Short Notice | P2: =CONCATENATE(G2," -> ",H2) -> Delhi -> Mumbai
A3: BK1001 | B3: FLT10006 | C3: RT1 | D3: AL105 | E3: {=IFERROR(INDEX(Airlines!$B:$B,MATCH(D3,Airlines!$A:$A,0)),"")} -> Vistara | F3: =VLOOKUP(A3,Bookings!$A:$F,6,FALSE()) -> Business | G3: {=IFERROR(INDEX(Flights!$E:$E,MATCH(B3,Flights!$A:$A,0)),"")} -> Delhi | H3: =VLOOKUP(B3,Flights!A:H,6,FALSE()) -> Mumbai | I3: {=IFERROR(INDEX(Bookings!$G:$G,MATCH(B3,Bookings!$B:$B,0)),"")} -> 0 | J3: =VLOOKUP(B3,Bookings!B:H,7,FALSE()) -> 2.08 | K3: =IF(J3<=4,"Short",IF(J3<=10,"Medium",IF(J3>10,"Long"))) -> Short | L3: {=IFERROR(INDEX(Bookings!$K:$K,MATCH(A3,Bookings!$A:$A,0)),"")} -> 28872 | M3: =IF(L3="","",IF(L3<=4631,"Low",IF(L3<=15800,"Medium","High"))) -> High | N3: {=IFERROR(INDEX(Bookings!$I:$I,MATCH(A3,Bookings!$A:$A,0)),"")} -> 15 | O3: =IF(N3<=7,"Last Minute",IF(N3<=15,"Short Notice",IF(N3<=30,"Moderate",IF(N3>=31,"Advance")))) -> Short Notice | P3: =CONCATENATE(G3," -> ",H3) -> Delhi -> Mumbai
A4: BK1002 | B4: FLT10010 | C4: RT1 | D4: AL102 | E4: {=IFERROR(INDEX(Airlines!$B:$B,MATCH(D4,Airlines!$A:$A,0)),"")} -> Go_First | F4: =VLOOKUP(A4,Bookings!$A:$F,6,FALSE()) -> Economy | G4: {=IFERROR(INDEX(Flights!$E:$E,MATCH(B4,Flights!$A:$A,0)),"")} -> Delhi | H4: =VLOOKUP(B4,Flights!A:H,6,FALSE()) -> Mumbai | I4: {=IFERROR(INDEX(Bookings!$G:$G,MATCH(B4,Bookings!$B:$B,0)),"")} -> 0 | J4: =VLOOKUP(B4,Bookings!B:H,7,FALSE()) -> 2.25 | K4: =IF(J4<=4,"Short",IF(J4<=10,"Medium",IF(J4>10,"Long"))) -> Short | L4: {=IFERROR(INDEX(Bookings!$K:$K,MATCH(A4,Bookings!$A:$A,0)),"")} -> 2410 | M4: =IF(L4="","",IF(L4<=4631,"Low",IF(L4<=15800,"Medium","High"))) -> Low | N4: {=IFERROR(INDEX(Bookings!$I:$I,MATCH(A4,Bookings!$A:$A,0)),"")} -> 30 | O4: =IF(N4<=7,"Last Minute",IF(N4<=15,"Short Notice",IF(N4<=30,"Moderate",IF(N4>=31,"Advance")))) -> Moderate | P4: =CONCATENATE(G4," -> ",H4) -> Delhi -> Mumbai
A5: BK1003 | B5: FLT10030 | C5: RT1 | D5: AL102 | E5: {=IFERROR(INDEX(Airlines!$B:$B,MATCH(D5,Airlines!$A:$A,0)),"")} -> Go_First | F5: =VLOOKUP(A5,Bookings!$A:$F,6,FALSE()) -> Economy | G5: {=IFERROR(INDEX(Flights!$E:$E,MATCH(B5,Flights!$A:$A,0)),"")} -> Delhi | H5: =VLOOKUP(B5,Flights!A:H,6,FALSE()) -> Mumbai | I5: {=IFERROR(INDEX(Bookings!$G:$G,MATCH(B5,Bookings!$B:$B,0)),"")} -> 1 | J5: =VLOOKUP(B5,Bookings!B:H,7,FALSE()) -> 8 | K5: =IF(J5<=4,"Short",IF(J5<=10,"Medium",IF(J5>10,"Long"))) -> Medium | L5: {=IFERROR(INDEX(Bookings!$K:$K,MATCH(A5,Bookings!$A:$A,0)),"")} -> 7907 | M5: =IF(L5="","",IF(L5<=4631,"Low",IF(L5<=15800,"Medium","High"))) -> Medium | N5: {=IFERROR(INDEX(Bookings!$I:$I,MATCH(A5,Bookings!$A:$A,0)),"")} -> 38 | O5: =IF(N5<=7,"Last Minute",IF(N5<=15,"Short Notice",IF(N5<=30,"Moderate",IF(N5>=31,"Advance")))) -> Advance | P5: =CONCATENATE(G5," -> ",H5) -> Delhi -> Mumbai
A6: BK1004 | B6: FLT10070 | C6: RT1 | D6: AL105 | E6: {=IFERROR(INDEX(Airlines!$B:$B,MATCH(D6,Airlines!$A:$A,0)),"")} -> Vistara | F6: =VLOOKUP(A6,Bookings!$A:$F,6,FALSE()) -> Business | G6: {=IFERROR(INDEX(Flights!$E:$E,MATCH(B6,Flights!$A:$A,0)),"")} -> Delhi | H6: =VLOOKUP(B6,Flights!A:H,6,FALSE()) -> Mumbai | I6: {=IFERROR(INDEX(Bookings!$G:$G,MATCH(B6,Bookings!$B:$B,0)),"")} -> 1 | J6: =VLOOKUP(B6,Bookings!B:H,7,FALSE()) -> 26.42 | K6: =IF(J6<=4,"Short",IF(J6<=10,"Medium",IF(J6>10,"Long"))) -> Long | L6: {=IFERROR(INDEX(Bookings!$K:$K,MATCH(A6,Bookings!$A:$A,0)),"")} -> 41281 | M6: =IF(L6="","",IF(L6<=4631,"Low",IF(L6<=15800,"Medium","High"))) -> High | N6: {=IFERROR(INDEX(Bookings!$I:$I,MATCH(A6,Bookings!$A:$A,0)),"")} -> 19 | O6: =IF(N6<=7,"Last Minute",IF(N6<=15,"Short Notice",IF(N6<=30,"Moderate",IF(N6>=31,"Advance")))) -> Moderate | P6: =CONCATENATE(G6," -> ",H6) -> Delhi -> Mumbai
A7: BK1005 | B7: FLT10073 | C7: RT1 | D7: AL105 | E7: {=IFERROR(INDEX(Airlines!$B:$B,MATCH(D7,Airlines!$A:$A,0)),"")} -> Vistara | F7: =VLOOKUP(A7,Bookings!$A:$F,6,FALSE()) -> Business | G7: {=IFERROR(INDEX(Flights!$E:$E,MATCH(B7,Flights!$A:$A,0)),"")} -> Delhi | H7: =VLOOKUP(B7,Flights!A:H,6,FALSE()) -> Mumbai | I7: {=IFERROR(INDEX(Bookings!$G:$G,MATCH(B7,Bookings!$B:$B,0)),"")} -> 1 | J7: =VLOOKUP(B7,Bookings!B:H,7,FALSE()) -> 13.83 | K7: =IF(J7<=4,"Short",IF(J7<=10,"Medium",IF(J7>10,"Long"))) -> Long | L7: {=IFERROR(INDEX(Bookings!$K:$K,MATCH(A7,Bookings!$A:$A,0)),"")} -> 70793 | M7: =IF(L7="","",IF(L7<=4631,"Low",IF(L7<=15800,"Medium","High"))) -> High | N7: {=IFERROR(INDEX(Bookings!$I:$I,MATCH(A7,Bookings!$A:$A,0)),"")} | O7: =IF(N7<=7,"Last Minute",IF(N7<=15,"Short Notice",IF(N7<=30,"Moderate",IF(N7>=31,"Advance")))) -> Last Minute | P7: =CONCATENATE(G7," -> ",H7) -> Delhi -> Mumbai
A8: BK1006 | B8: FLT10077 | C8: RT1 | D8: AL105 | E8: {=IFERROR(INDEX(Airlines!$B:$B,MATCH(D8,Airlines!$A:$A,0)),"")} -> Vistara | F8: =VLOOKUP(A8,Bookings!$A:$F,6,FALSE()) -> Economy | G8: {=IFERROR(INDEX(Flights!$E:$E,MATCH(B8,Flights!$A:$A,0)),"")} -> Delhi | H8: =VLOOKUP(B8,Flights!A:H,6,FALSE()) -> Mumbai | I8: {=IFERROR(INDEX(Bookings!$G:$G,MATCH(B8,Bookings!$B:$B,0)),"")} -> 1 | J8: =VLOOKUP(B8,Bookings!B:H,7,FALSE()) -> 24.42 | K8: =IF(J8<=4,"Short",IF(J8<=10,"Medium",IF(J8>10,"Long"))) -> Long | L8: {=IFERROR(INDEX(Bookings!$K:$K,MATCH(A8,Bookings!$A:$A,0)),"")} -> 17348 | M8: =IF(L8="","",IF(L8<=4631,"Low",IF(L8<=15800,"Medium","High"))) -> High | N8: {=IFERROR(INDEX(Bookings!$I:$I,MATCH(A8,Bookings!$A:$A,0)),"")} -> 2 | O8: =IF(N8<=7,"Last Minute",IF(N8<=15,"Short Notice",IF(N8<=30,"Moderate",IF(N8>=31,"Advance")))) -> Last Minute | P8: =CONCATENATE(G8," -> ",H8) -> Delhi -> Mumbai
A9: BK1007 | B9: FLT10078 | C9: RT1 | D9: AL105 | E9: {=IFERROR(INDEX(Airlines!$B:$B,MATCH(D9,Airlines!$A:$A,0)),"")} -> Vistara | F9: =VLOOKUP(A9,Bookings!$A:$F,6,FALSE()) -> Economy | G9: {=IFERROR(INDEX(Flights!$E:$E,MATCH(B9,Flights!$A:$A,0)),"")} -> Delhi | H9: =VLOOKUP(B9,Flights!A:H,6,FALSE()) -> Mumbai | I9: {=IFERROR(INDEX(Bookings!$G:$G,MATCH(B9,Bookings!$B:$B,0)),"")} -> 1 | J9: =VLOOKUP(B9,Bookings!B:H,7,FALSE()) -> 26 | K9: =IF(J9<=4,"Short",IF(J9<=10,"Medium",IF(J9>10,"Long"))) -> Long | L9: {=IFERROR(INDEX(Bookings!$K:$K,MATCH(A9,Bookings!$A:$A,0)),"")} -> 15353 | M9: =IF(L9="","",IF(L9<=4631,"Low",IF(L9<=15800,"Medium","High"))) -> Medium | N9: {=IFERROR(INDEX(Bookings!$I:$I,MATCH(A9,Bookings!$A:$A,0)),"")} -> 2 | O9: =IF(N9<=7,"Last Minute",IF(N9<=15,"Short Notice",IF(N9<=30,"Moderate",IF(N9>=31,"Advance")))) -> Last Minute | P9: =CONCATENATE(G9," -> ",H9) -> Delhi -> Mumbai
A10: BK1008 | B10: FLT10079 | C10: RT1 | D10: AL103 | E10: {=IFERROR(INDEX(Airlines!$B:$B,MATCH(D10,Airlines!$A:$A,0)),"")} -> Indigo | F10: =VLOOKUP(A10,Bookings!$A:$F,6,FALSE()) -> Economy | G10: {=IFERROR(INDEX(Flights!$E:$E,MATCH(B10,Flights!$A:$A,0)),"")} -> Delhi | H10: =VLOOKUP(B10,Flights!A:H,6,FALSE()) -> Mumbai | I10: {=IFERROR(INDEX(Bookings!$G:$G,MATCH(B10,Bookings!$B:$B,0)),"")} -> 1 | J10: =VLOOKUP(B10,Bookings!B:H,7,FALSE()) -> 4.17 | K10: =IF(J10<=4,"Short",IF(J10<=10,"Medium",IF(J10>10,"Long"))) -> Medium | L10: {=IFERROR(INDEX(Bookings!$K:$K,MATCH(A10,Bookings!$A:$A,0)),"")} -> 3054 | M10: =IF(L10="","",IF(L10<=4631,"Low",IF(L10<=15800,"Medium","High"))) -> Low | N10: {=IFERROR(INDEX(Bookings!$I:$I,MATCH(A10,Bookings!$A:$A,0)),"")} -> 38 | O10: =IF(N10<=7,"Last Minute",IF(N10<=15,"Short Notice",IF(N10<=30,"Moderate",IF(N10>=31,"Advance")))) -> Advance | P10: =CONCATENATE(G10," -> ",H10) -> Delhi -> Mumbai
A11: BK1009 | B11: FLT10081 | C11: RT1 | D11: AL103 | E11: {=IFERROR(INDEX(Airlines!$B:$B,MATCH(D11,Airlines!$A:$A,0)),"")} -> Indigo | F11: =VLOOKUP(A11,Bookings!$A:$F,6,FALSE()) -> Economy | G11: {=IFERROR(INDEX(Flights!$E:$E,MATCH(B11,Flights!$A:$A,0)),"")} -> Delhi | H11: =VLOOKUP(B11,Flights!A:H,6,FALSE()) -> Mumbai | I11: {=IFERROR(INDEX(Bookings!$G:$G,MATCH(B11,Bookings!$B:$B,0)),"")} -> 1 | J11: =VLOOKUP(B11,Bookings!B:H,7,FALSE()) -> 5.08 | K11: =IF(J11<=4,"Short",IF(J11<=10,"Medium",IF(J11>10,"Long"))) -> Medium | L11: {=IFERROR(INDEX(Bookings!$K:$K,MATCH(A11,Bookings!$A:$A,0)),"")} -> 3631 | M11: =IF(L11="","",IF(L11<=4631,"Low",IF(L11<=15800,"Medium","High"))) -> Low | N11: {=IFERROR(INDEX(Bookings!$I:$I,MATCH(A11,Bookings!$A:$A,0)),"")} -> 39 | O11: =IF(N11<=7,"Last Minute",IF(N11<=15,"Short Notice",IF(N11<=30,"Moderate",IF(N11>=31,"Advance")))) -> Advance | P11: =CONCATENATE(G11," -> ",H11) -> Delhi -> Mumbai
A12: BK1010 | B12: FLT10082 | C12: RT1 | D12: AL101 | E12: {=IFERROR(INDEX(Airlines!$B:$B,MATCH(D12,Airlines!$A:$A,0)),"")} -> Air_India | F12: =VLOOKUP(A12,Bookings!$A:$F,6,FALSE()) -> Economy | G12: {=IFERROR(INDEX(Flights!$E:$E,MATCH(B12,Flights!$A:$A,0)),"")} -> Delhi | H12: =VLOOKUP(B12,Flights!A:H,6,FALSE()) -> Mumbai | I12: {=IFERROR(INDEX(Bookings!$G:$G,MATCH(B12,Bookings!$B:$B,0)),"")} -> 1 | J12: =VLOOKUP(B12,Bookings!B:H,7,FALSE()) -> 29.33 | K12: =IF(J12<=4,"Short",IF(J12<=10,"Medium",IF(J12>10,"Long"))) -> Long | L12: {=IFERROR(INDEX(Bookings!$K:$K,MATCH(A12,Bookings!$A:$A,0)),"")} -> 16245 | M12: =IF(L12="","",IF(L12<=4631,"Low",IF(L12<=15800,"Medium","High"))) -> High | N12: {=IFERROR(INDEX(Bookings!$I:$I,MATCH(A12,Bookings!$A:$A,0)),"")} | O12: =IF(N12<=7,"Last Minute",IF(N12<=15,"Short Notice",IF(N12<=30,"Moderate",IF(N12>=31,"Advance")))) -> Last Minute | P12: =CONCATENATE(G12," -> ",H12) -> Delhi -> Mumbai
A13: BK1011 | B13: FLT10083 | C13: RT1 | D13: AL105 | E13: {=IFERROR(INDEX(Airlines!$B:$B,MATCH(D13,Airlines!$A:$A,0)),"")} -> Vistara | F13: =VLOOKUP(A13,Bookings!$A:$F,6,FALSE()) -> Economy | G13: {=IFERROR(INDEX(Flights!$E:$E,MATCH(B13,Flights!$A:$A,0)),"")} -> Delhi | H13: =VLOOKUP(B13,Flights!A:H,6,FALSE()) -> Mumbai | I13: {=IFERROR(INDEX(Bookings!$G:$G,MATCH(B13,Bookings!$B:$B,0)),"")} -> 1 | J13: =VLOOKUP(B13,Bookings!B:H,7,FALSE()) -> 4.42 | K13: =IF(J13<=4,"Short",IF(J13<=10,"Medium",IF(J13>10,"Long"))) -> Medium | L13: {=IFERROR(INDEX(Bookings!$K:$K,MATCH(A13,Bookings!$A:$A,0)),"")} -> 4381 | M13: =IF(L13="","",IF(L13<=4631,"Low",IF(L13<=15800,"Medium","High"))) -> Low | N13: {=IFERROR(INDEX(Bookings!$I:$I,MATCH(A13,Bookings!$A:$A,0)),"")} -> 46 | O13: =IF(N13<=7,"Last Minute",IF(N13<=15,"Short Notice",IF(N13<=30,"Moderate",IF(N13>=31,"Advance")))) -> Advance | P13: =CONCATENATE(G13," -> ",H13) -> Delhi -> Mumbai
... A1201: BK2199 | B1201: FLT22952 | C1201: RT30 | D1201: AL105 | E1201: {=IFERROR(INDEX(Airlines!$B:$B,MATCH(D1201,Airlines!$A:$A,0)),"")} -> Vistara | F1201: =VLOOKUP(A1201,Bookings!$A:$F,6,FALSE()) -> Business | G1201: {=IFERROR(INDEX(Flights!$E:$E,MATCH(B1201,Flights!$A:$A,0)),"")} -> Chennai | H1201: =VLOOKUP(B1201,Flights!A:H,6,FALSE()) -> Hyderabad | I1201: {=IFERROR(INDEX(Bookings!$G:$G,MATCH(B1201,Bookings!$B:$B,0)),"")} -> 1 | J1201: =VLOOKUP(B1201,Bookings!B:H,7,FALSE()) -> 26.5 | K1201: =IF(J1201<=4,"Short",IF(J1201<=10,"Medium",IF(J1201>10,"Long"))) -> Long | L1201: {=IFERROR(INDEX(Bookings!$K:$K,MATCH(A1201,Bookings!$A:$A,0)),"")} -> 51457 | M1201: =IF(L1201="","",IF(L1201<=4631,"Low",IF(L1201<=15800,"Medium","High"))) -> High | N1201: {=IFERROR(INDEX(Bookings!$I:$I,MATCH(A1201,Bookings!$A:$A,0)),"")} -> 44 | O1201: =IF(N1201<=7,"Last Minute",IF(N1201<=15,"Short Notice",IF(N1201<=30,"Moderate",IF(N1201>=31,"Advance")))) -> Advance | P1201: =CONCATENATE(G1201," -> ",H1201) -> Chennai -> Hyderabad

Sheet Pivot Table
E1: Flight Booking and Travel Data Analysis
C3: Airline Class Performance | G3: Airline-wise Price Analysis
B5: Row Labels | C5: Total Economy_Bookings | D5: Total Business_Bookings | E5: Total_Bookings | G5: Row Labels | H5: Avg_Price | I5: Min_Price | J5: Max_Price
B6: Air_India | C6: 314 | D6: 107 | E6: 421 | G6: Air_India | H6: 18373.679 | I6: 1526 | J6: 75382
B7: AirAsia | C7: 61 | D7: 0 | E7: 61 | G7: AirAsia | H7: 3930.5246 | I7: 1443 | J7: 7484
B8: Go_First | C8: 109 | D8: 0 | E8: 109 | G8: Go_First | H8: 6339.7156 | I8: 2124 | J8: 31773
B9: Indigo | C9: 225 | D9: 0 | E9: 225 | G9: Indigo | H9: 5847.9778 | I9: 1105 | J9: 24561
B10: Spicejet | C10: 46 | D10: 0 | E10: 46 | G10: Spicejet | H10: 6134.9783 | I10: 1566 | J10: 27769
B11: Vistara | C11: 222 | D11: 116 | E11: 338 | G11: Vistara | H11: 25590.518 | I11: 1776 | J11: 110936
B12: Grand Total | C12: 977 | D12: 223 | E12: 1200 | G12: Grand Total | H12: 11036.232 | I12: 1105 | J12: 110936
C15: Route-wise Booking Analysis | H15: Booking Window Analysis
B17: Row Labels | C17: Average of Duration_Hrs | D17: Average of Price | E17: Count of Booking_Id | G17: Row Labels | H17: Count of Booking_Id | I17: Average of Price
B18: Bengaluru -> Chennai | C18: 18.53525 | D18: 14582.425 | E18: 40 | G18: Advance | H18: 602 | I18: 13951.683
B19: Bengaluru -> Delhi | C19: 11.719 | D19: 11995.55 | E19: 40 | G19: Last Minute | H19: 313 | I19: 20829.307
B20: Bengaluru -> Hyderabad | C20: 15.93575 | D20: 16989.55 | E20: 40 | G20: Moderate | H20: 165 | I20: 12276.576
B21: Bengaluru -> Kolkata | C21: 13.79175 | D21: 16061.4 | E21: 40 | G21: Short Notice | H21: 120 | I21: 16413.233
B22: Bengaluru -> Mumbai | C22: 13.833 | D22: 19002.775 | E22: 40 | G22: Grand Total | H22: 1200 | I22: 15761.424
B23: Chennai -> Bengaluru | C23: 16.285 | D23: 18646.675 | E23: 40
B24: Chennai -> Delhi | C24: 15.34225 | D24: 20347.425 | E24: 40
B25: Chennai -> Hyderabad | C25: 13.09225 | D25: 13911.7 | E25: 40 | H25: Class-wise Price Analysis
B26: Chennai -> Kolkata | C26: 16.3835 | D26: 15552.85 | E26: 40
B27: Chennai -> Mumbai | C27: 16.2855 | D27: 17543.25 | E27: 40 | G27: Row Labels | H27: Count of Booking_Id | I27: Average of Price | J27: Min of Price | K27: Max of Price
B28: Delhi -> Bengaluru | C28: 11.6415 | D28: 13093.1 | E28: 40 | G28: Business | H28: 223 | I28: 49772.157 | J28: 7336 | K28: 110936
B29: Delhi -> Chennai | C29: 15.8045 | D29: 19602.975 | E29: 40 | G29: Economy | H29: 977 | I29: 7998.4831 | J29: 1105 | K29: 33813
B30: Delhi -> Hyderabad | C30: 12.65425 | D30: 12376.25 | E30: 40 | G30: Grand Total | H30: 1200 | I30: 15761.424 | J30: 1105 | K30: 110936
B31: Delhi -> Kolkata | C31: 14.379 | D31: 13356.975 | E31: 40
B32: Delhi -> Mumbai | C32: 10.9085 | D32: 15969.15 | E32: 40
B33: Hyderabad -> Bengaluru | C33: 13.367 | D33: 13713.85 | E33: 40
B34: Hyderabad -> Chennai | C34: 12.5145 | D34: 13727.85 | E34: 40
B35: Hyderabad -> Delhi | C35: 13.10825 | D35: 16088.125 | E35: 40
B36: Hyderabad -> Kolkata | C36: 16.3605 | D36: 17361.975 | E36: 40
B37: Hyderabad -> Mumbai | C37: 14.707 | D37: 16356.95 | E37: 40
B38: Kolkata -> Bengaluru | C38: 13.96075 | D38: 12438.45 | E38: 40
B39: Kolkata -> Chennai | C39: 14.34825 | D39: 12966.7 | E39: 40
B40: Kolkata -> Delhi | C40: 14.75825 | D40: 18093.675 | E40: 40
B41: Kolkata -> Hyderabad | C41: 16.233 | D41: 14967.15 | E41: 40
B42: Kolkata -> Mumbai | C42: 16.566 | D42: 19956.725 | E42: 40
... B48: Grand Total | C48: 14.446075 | D48: 15761.424 | E48: 1200

Sheet Descriptive Statistics
D1: Descriptive Statistics
A2: Total_Bookings | C2: Routes_Covered | E2: Avg_Price | G2: Min_Price | I2: Max_Price
A4: Mean | B4: 200 | C4: Mean | D4: 27.5 | E4: Mean | F4: 11036.232 | G4: Mean | H4: 1590 | I4: Mean | J4: 46317.5
A5: Standard Error | B5: 63.200211 | C5: Standard Error | D5: 1.3102163 | E5: Standard Error | F5: 3601.6384 | G5: Standard Error | H5: 139.19507 | I5: Standard Error | J5: 15871.642
A6: Median | B6: 167 | C6: Median | D6: 28.5 | E6: Median | F6: 6237.3469 | G6: Median | H6: 1546 | I6: Median | J6: 29771
A7: Mode | B7: =#N/A -> #N/A | C7: Mode | D7: 30 | E7: Mode | F7: =#N/A -> #N/A | G7: Mode | H7: =#N/A -> #N/A | I7: Mode | J7: =#N/A -> #N/A
A8: Standard Deviation | B8: 154.80827 | C8: Standard Deviation | D8: 3.2093613 | E8: Standard Deviation | F8: 8822.1764 | G8: Standard Deviation | H8: 340.95689 | I8: Standard Deviation | J8: 38877.425
A9: Sample Variance | B9: 23965.6 | C9: Sample Variance | D9: 10.3 | E9: Sample Variance | F9: 77830796 | G9: Sample Variance | H9: 116251.6 | I9: Sample Variance | J9: 1.5114542e+09
A10: Kurtosis | B10: -1.6761638 | C10: Kurtosis | D10: 0.59477802 | E10: Kurtosis | F10: -0.22870615 | G10: Kurtosis | H10: 0.91478223 | I10: Kurtosis | J10: 0.12652168
A11: Skewness | B11: 0.51315195 | C11: Skewness | D11: -1.1162733 | E11: Skewness | F11: 1.2051191 | G11: Skewness | H11: 0.31161618 | I11: Skewness | J11: 1.1030229
A12: Range | B12: 375 | C12: Range | D12: 8 | E12: Range | F12: 21659.993 | G12: Range | H12: 1019 | I12: Range | J12: 103452
A13: Minimum | B13: 46 | C13: Minimum | D13: 22 | E13: Minimum | F13: 3930.5246 | G13: Minimum | H13: 1105 | I13: Minimum | J13: 7484
A14: Maximum | B14: 421 | C14: Maximum | D14: 30 | E14: Maximum | F14: 25590.518 | G14: Maximum | H14: 2124 | I14: Maximum | J14: 110936
A15: Sum | B15: 1200 | C15: Sum | D15: 165 | E15: Sum | F15: 66217.393 | G15: Sum | H15: 9540 | I15: Sum | J15: 277905
A16: Count | B16: 6 | C16: Count | D16: 6 | E16: Count | F16: 6 | G16: Count | H16: 6 | I16: Count | J16: 6
